2023-11-07 19:35:47 WARNING Retrying (Retry(total=2, connect=None, read=None, redirect=None, status=None)) after connection broken by 'NewConnectionError('<urllib3.connection.HTTPSConnection object at 0x0000025D31BAA070>: Failed to establish a new connection: [WinError 10061] 由于目标计算机积极拒绝，无法连接。')': /api/4504800232407040/envelope/
2023-11-07 19:38:24 WARNING Retrying (Retry(total=2, connect=None, read=None, redirect=None, status=None)) after connection broken by 'OSError(0, 'Error')': /api/4504800232407040/envelope/
2023-11-07 19:38:24 WARNING Retrying (Retry(total=1, connect=None, read=None, redirect=None, status=None)) after connection broken by 'OSError(0, 'Error')': /api/4504800232407040/envelope/
2023-11-07 19:38:24 WARNING Retrying (Retry(total=0, connect=None, read=None, redirect=None, status=None)) after connection broken by 'OSError(0, 'Error')': /api/4504800232407040/envelope/
2023-11-07 19:38:24 WARNING Retrying (Retry(total=2, connect=None, read=None, redirect=None, status=None)) after connection broken by 'OSError(0, 'Error')': /api/4504800232407040/envelope/
2023-11-07 19:38:24 WARNING Retrying (Retry(total=1, connect=None, read=None, redirect=None, status=None)) after connection broken by 'OSError(0, 'Error')': /api/4504800232407040/envelope/
2023-11-07 19:38:24 WARNING Retrying (Retry(total=0, connect=None, read=None, redirect=None, status=None)) after connection broken by 'OSError(0, 'Error')': /api/4504800232407040/envelope/
2023-11-07 19:40:17 WARNING Retrying (Retry(total=2, connect=None, read=None, redirect=None, status=None)) after connection broken by 'OSError(0, 'Error')': /api/4504800232407040/envelope/
2023-11-07 19:40:17 WARNING Retrying (Retry(total=1, connect=None, read=None, redirect=None, status=None)) after connection broken by 'OSError(0, 'Error')': /api/4504800232407040/envelope/
2023-11-07 19:40:17 WARNING Retrying (Retry(total=0, connect=None, read=None, redirect=None, status=None)) after connection broken by 'OSError(0, 'Error')': /api/4504800232407040/envelope/
2023-11-07 19:40:17 WARNING Retrying (Retry(total=2, connect=None, read=None, redirect=None, status=None)) after connection broken by 'OSError(0, 'Error')': /api/4504800232407040/envelope/
2023-11-07 19:40:17 WARNING Retrying (Retry(total=1, connect=None, read=None, redirect=None, status=None)) after connection broken by 'OSError(0, 'Error')': /api/4504800232407040/envelope/
2023-11-07 19:40:17 WARNING Retrying (Retry(total=0, connect=None, read=None, redirect=None, status=None)) after connection broken by 'OSError(0, 'Error')': /api/4504800232407040/envelope/
2023-11-07 19:46:23 WARNING Retrying (Retry(total=2, connect=None, read=None, redirect=None, status=None)) after connection broken by 'OSError(0, 'Error')': /api/4504800232407040/envelope/
2023-11-07 19:46:23 WARNING Retrying (Retry(total=1, connect=None, read=None, redirect=None, status=None)) after connection broken by 'OSError(0, 'Error')': /api/4504800232407040/envelope/
2023-11-07 19:46:23 WARNING Retrying (Retry(total=0, connect=None, read=None, redirect=None, status=None)) after connection broken by 'OSError(0, 'Error')': /api/4504800232407040/envelope/
2023-11-07 19:46:23 WARNING Retrying (Retry(total=2, connect=None, read=None, redirect=None, status=None)) after connection broken by 'OSError(0, 'Error')': /api/4504800232407040/envelope/
2023-11-07 19:46:23 WARNING Retrying (Retry(total=1, connect=None, read=None, redirect=None, status=None)) after connection broken by 'OSError(0, 'Error')': /api/4504800232407040/envelope/
2023-11-07 19:46:23 WARNING Retrying (Retry(total=0, connect=None, read=None, redirect=None, status=None)) after connection broken by 'OSError(0, 'Error')': /api/4504800232407040/envelope/
2023-11-07 19:46:41 INFO Retry attempt failed:
Traceback (most recent call last):
  File "C:\Users\29660\.conda\envs\yolo5\lib\site-packages\urllib3\connectionpool.py", line 777, in urlopen
    self._prepare_proxy(conn)
  File "C:\Users\29660\.conda\envs\yolo5\lib\site-packages\urllib3\connectionpool.py", line 1046, in _prepare_proxy
    conn.connect()
  File "C:\Users\29660\.conda\envs\yolo5\lib\site-packages\urllib3\connection.py", line 619, in connect
    self.sock = sock = self._connect_tls_proxy(self.host, sock)
  File "C:\Users\29660\.conda\envs\yolo5\lib\site-packages\urllib3\connection.py", line 675, in _connect_tls_proxy
    sock_and_verified = _ssl_wrap_socket_and_match_hostname(
  File "C:\Users\29660\.conda\envs\yolo5\lib\site-packages\urllib3\connection.py", line 783, in _ssl_wrap_socket_and_match_hostname
    ssl_sock = ssl_wrap_socket(
  File "C:\Users\29660\.conda\envs\yolo5\lib\site-packages\urllib3\util\ssl_.py", line 471, in ssl_wrap_socket
    ssl_sock = _ssl_wrap_socket_impl(sock, context, tls_in_tls, server_hostname)
  File "C:\Users\29660\.conda\envs\yolo5\lib\site-packages\urllib3\util\ssl_.py", line 515, in _ssl_wrap_socket_impl
    return ssl_context.wrap_socket(sock, server_hostname=server_hostname)
  File "C:\Users\29660\.conda\envs\yolo5\lib\ssl.py", line 500, in wrap_socket
    return self.sslsocket_class._create(
  File "C:\Users\29660\.conda\envs\yolo5\lib\ssl.py", line 1040, in _create
    self.do_handshake()
  File "C:\Users\29660\.conda\envs\yolo5\lib\ssl.py", line 1309, in do_handshake
    self._sslobj.do_handshake()
OSError: [Errno 0] Error

The above exception was the direct cause of the following exception:

urllib3.exceptions.ProxyError: ('Unable to connect to proxy', OSError(0, 'Error'))

The above exception was the direct cause of the following exception:

Traceback (most recent call last):
  File "C:\Users\29660\.conda\envs\yolo5\lib\site-packages\requests\adapters.py", line 486, in send
    resp = conn.urlopen(
  File "C:\Users\29660\.conda\envs\yolo5\lib\site-packages\urllib3\connectionpool.py", line 845, in urlopen
    retries = retries.increment(
  File "C:\Users\29660\.conda\envs\yolo5\lib\site-packages\urllib3\util\retry.py", line 515, in increment
    raise MaxRetryError(_pool, url, reason) from reason  # type: ignore[arg-type]
urllib3.exceptions.MaxRetryError: HTTPSConnectionPool(host='api.wandb.ai', port=443): Max retries exceeded with url: /graphql (Caused by ProxyError('Unable to connect to proxy', OSError(0, 'Error')))

During handling of the above exception, another exception occurred:

Traceback (most recent call last):
  File "C:\Users\29660\.conda\envs\yolo5\lib\site-packages\wandb\sdk\lib\retry.py", line 131, in __call__
    result = self._call_fn(*args, **kwargs)
  File "C:\Users\29660\.conda\envs\yolo5\lib\site-packages\wandb\sdk\internal\internal_api.py", line 366, in execute
    return self.client.execute(*args, **kwargs)  # type: ignore
  File "C:\Users\29660\.conda\envs\yolo5\lib\site-packages\wandb\vendor\gql-0.2.0\wandb_gql\client.py", line 52, in execute
    result = self._get_result(document, *args, **kwargs)
  File "C:\Users\29660\.conda\envs\yolo5\lib\site-packages\wandb\vendor\gql-0.2.0\wandb_gql\client.py", line 60, in _get_result
    return self.transport.execute(document, *args, **kwargs)
  File "C:\Users\29660\.conda\envs\yolo5\lib\site-packages\wandb\sdk\lib\gql_request.py", line 58, in execute
    request = self.session.post(self.url, **post_args)
  File "C:\Users\29660\.conda\envs\yolo5\lib\site-packages\requests\sessions.py", line 637, in post
    return self.request("POST", url, data=data, json=json, **kwargs)
  File "C:\Users\29660\.conda\envs\yolo5\lib\site-packages\requests\sessions.py", line 589, in request
    resp = self.send(prep, **send_kwargs)
  File "C:\Users\29660\.conda\envs\yolo5\lib\site-packages\requests\sessions.py", line 703, in send
    r = adapter.send(request, **kwargs)
  File "C:\Users\29660\.conda\envs\yolo5\lib\site-packages\requests\adapters.py", line 513, in send
    raise ProxyError(e, request=request)
requests.exceptions.ProxyError: HTTPSConnectionPool(host='api.wandb.ai', port=443): Max retries exceeded with url: /graphql (Caused by ProxyError('Unable to connect to proxy', OSError(0, 'Error')))
2023-11-07 19:46:43 WARNING Retrying (Retry(total=2, connect=None, read=None, redirect=None, status=None)) after connection broken by 'OSError(0, 'Error')': /api/4504800232407040/envelope/
2023-11-07 19:46:43 WARNING Retrying (Retry(total=1, connect=None, read=None, redirect=None, status=None)) after connection broken by 'OSError(0, 'Error')': /api/4504800232407040/envelope/
2023-11-07 19:46:43 WARNING Retrying (Retry(total=0, connect=None, read=None, redirect=None, status=None)) after connection broken by 'OSError(0, 'Error')': /api/4504800232407040/envelope/
2023-11-07 19:46:43 WARNING Retrying (Retry(total=2, connect=None, read=None, redirect=None, status=None)) after connection broken by 'OSError(0, 'Error')': /api/4504800232407040/envelope/
2023-11-07 19:46:43 WARNING Retrying (Retry(total=1, connect=None, read=None, redirect=None, status=None)) after connection broken by 'OSError(0, 'Error')': /api/4504800232407040/envelope/
2023-11-07 19:46:43 WARNING Retrying (Retry(total=0, connect=None, read=None, redirect=None, status=None)) after connection broken by 'OSError(0, 'Error')': /api/4504800232407040/envelope/
2023-11-07 19:48:51 WARNING Retrying (Retry(total=2, connect=None, read=None, redirect=None, status=None)) after connection broken by 'OSError(0, 'Error')': /api/4504800232407040/envelope/
2023-11-07 19:48:51 WARNING Retrying (Retry(total=1, connect=None, read=None, redirect=None, status=None)) after connection broken by 'OSError(0, 'Error')': /api/4504800232407040/envelope/
2023-11-07 19:48:51 WARNING Retrying (Retry(total=0, connect=None, read=None, redirect=None, status=None)) after connection broken by 'OSError(0, 'Error')': /api/4504800232407040/envelope/
2023-11-07 19:48:51 WARNING Retrying (Retry(total=2, connect=None, read=None, redirect=None, status=None)) after connection broken by 'OSError(0, 'Error')': /api/4504800232407040/envelope/
2023-11-07 19:48:51 WARNING Retrying (Retry(total=1, connect=None, read=None, redirect=None, status=None)) after connection broken by 'OSError(0, 'Error')': /api/4504800232407040/envelope/
2023-11-07 19:48:51 WARNING Retrying (Retry(total=0, connect=None, read=None, redirect=None, status=None)) after connection broken by 'OSError(0, 'Error')': /api/4504800232407040/envelope/
2023-11-07 19:50:48 WARNING Retrying (Retry(total=2, connect=None, read=None, redirect=None, status=None)) after connection broken by 'OSError(0, 'Error')': /api/4504800232407040/envelope/
2023-11-07 19:50:48 WARNING Retrying (Retry(total=1, connect=None, read=None, redirect=None, status=None)) after connection broken by 'OSError(0, 'Error')': /api/4504800232407040/envelope/
2023-11-07 19:50:48 WARNING Retrying (Retry(total=0, connect=None, read=None, redirect=None, status=None)) after connection broken by 'OSError(0, 'Error')': /api/4504800232407040/envelope/
2023-11-07 19:50:48 WARNING Retrying (Retry(total=2, connect=None, read=None, redirect=None, status=None)) after connection broken by 'OSError(0, 'Error')': /api/4504800232407040/envelope/
2023-11-07 19:50:48 WARNING Retrying (Retry(total=1, connect=None, read=None, redirect=None, status=None)) after connection broken by 'OSError(0, 'Error')': /api/4504800232407040/envelope/
2023-11-07 19:50:48 WARNING Retrying (Retry(total=0, connect=None, read=None, redirect=None, status=None)) after connection broken by 'OSError(0, 'Error')': /api/4504800232407040/envelope/
2023-11-07 19:56:58 WARNING Retrying (Retry(total=2, connect=None, read=None, redirect=None, status=None)) after connection broken by 'OSError(0, 'Error')': /api/4504800232407040/envelope/
2023-11-07 19:56:58 WARNING Retrying (Retry(total=1, connect=None, read=None, redirect=None, status=None)) after connection broken by 'OSError(0, 'Error')': /api/4504800232407040/envelope/
2023-11-07 19:56:58 WARNING Retrying (Retry(total=0, connect=None, read=None, redirect=None, status=None)) after connection broken by 'OSError(0, 'Error')': /api/4504800232407040/envelope/
2023-11-07 19:56:58 WARNING Retrying (Retry(total=2, connect=None, read=None, redirect=None, status=None)) after connection broken by 'OSError(0, 'Error')': /api/4504800232407040/envelope/
2023-11-07 19:56:58 WARNING Retrying (Retry(total=1, connect=None, read=None, redirect=None, status=None)) after connection broken by 'OSError(0, 'Error')': /api/4504800232407040/envelope/
2023-11-07 19:56:58 WARNING Retrying (Retry(total=0, connect=None, read=None, redirect=None, status=None)) after connection broken by 'OSError(0, 'Error')': /api/4504800232407040/envelope/
